---
title: 12. 两个Promise对象相加 - 简单
---
题目：
给定两个 promise 对象 `promise1` 和 `promise2`，返回一个新的 promise。`promise1` 和 `promise2` 都会被解析为一个数字。返回的 Promise 应该解析为这两个数字的和。

**示例 1：**

**输入：**
promise1 = new Promise(resolve => setTimeout(() => resolve(2), 20)), 
promise2 = new Promise(resolve => setTimeout(() => resolve(5), 60))
**输出：** 7
**解释：** 两个输入的 Promise 分别解析为值 2 和 5。返回的 Promise 应该解析为 2 + 5 = 7。返回的 Promise 解析的时间不作为判断条件。

答案：
```js
var addTwoPromises = async function(promise1, promise2) {
    try{
        const [res1,res2] = await Promise.all([promise1,promise2]);
        return res1+res2
    } catch(error){
        console.log(error);
        throw error;
    }
};
```
注意要点：针对promise对象，代码尽量都写在try catch块里
`Promise.all()`的参数传递需要是数组。
通过解构方式将两个结果提取出来。

直接使用await：
```js
var addTwoPromises = async function(promise1,promise2){
	try{
		return await promise1 + await promise2;
	}catch(error){
		console.log(error);
		throw error
	}
}
```

使用`.then()`
```js
var addTwoPromises = async function(promise1,promise2){
	try{
	return promise1.then((val1) => promise2.then((val2) => val1+val2))
	}catch(error){
		console.log(error);
		throw error
	}
}
```


本题解决js里的promise对象

### `Promise`

在js里Promise用于表示异步操作最终完成或失败，并允许我们在结果可用时进行处理。
Promise有三种状态：pending、fulfilled、rejected。
Promise提供了`.then()`和`.catch()`的方法处理已解析的值或错误。

通常会遇到`async`和`await`关键字

async：用于定义异步函数，确保函数始终返回一个 Promise。当在函数声明或函数表达式前使用 async 关键字时，它变成一个异步函数。请注意，从异步函数返回的非 Promise 对象会自动包装成 Promise 对象。

await：用于暂停异步函数的执行，直到 Promise 解析。它只能在异步函数内部使用。当在 Promise 之前使用 await 时，它等待 Promise 解析或拒绝。如果已解析，它继续执行下一行代码；如果等待的 Promise 被拒绝，将抛出异常。使用 await 允许您以更顺序且可读的方式编写异步代码，而无需使用 .then() 显式链接 Promise。

### `Promise.all()`
当有多个异步操作需要同时执行并等待全部完成，通常使用`Promise.all()`
Promise.all() 不仅接受 Promise 作为输入，还可以接受只包含数字的数组，它将解析这些数字，例如：

```js
await Promise.all([1, 2, Promise.resolve(3), Promise.resolve(4)]).then((value) => {
  console.log(value)
}, (error) => {
  console.log(error)
})
```
如果所有 Promise 都被解决，返回的 Promise 也会被解决，而输入 Promise 的已解析值将按照输入 Promise 的顺序作为数组可用。

如果任何 Promise 被拒绝，返回的 Promise 将被拒绝，并将使用第一个被拒绝的Promise的原因。例如，下面的代码将解析为 'error'，尽管其他项目都已正确解析。

```js
await Promise.all([1, 2, Promise.resolve(3), Promise.reject('error')]).then(
value => {
  console.log(value);
},
error => {
  console.log(error);
}
);
```
使用 Promise.all() 允许有效并行执行多个异步操作，并在它们全部可用后处理合并的结果。

例如，当应用程序需要同时从多个 API 获取数据时，可以使用 Promise.all() 来并行启动所有请求并等待所有响应。一旦所有 Promise 都被解决，应用程序可以处理合并数据。


### 面试小贴士：
#### `Promise.all()`方法的作用是什么？

`Promise.all()` 方法用于同时处理多个 Promise。它以一个 Promise 数组作为输入，并返回一个新的 Promise。这个新的 Promise 在输入数组中的所有 Promise 都已解决时才会解决。已解析的 Promise 的值在 .then() 块中作为数组按照输入 Promise 的顺序可用。

#### 如何处理 Promise 中的错误？

可以使用 `try {} catch(err) {} finally` 块来处理 Promise 链中的错误。

#### 同步操作和异步操作之间有什么区别？

同步操作会阻止程序的执行，直到操作完成。它们以顺序方式一个接一个地执行。而异步操作不会阻止程序的执行，它们允许程序在等待操作完成时继续执行其他任务。异步操作通常用于可能需要较长时间才能完成的任务，例如网络请求或文件操作，以避免阻塞主执行线程。

#### JavaScript 中回调函数和 Promise 之间有什么区别？什么时候更喜欢使用 Promise 而不是回调？另外，回调地狱是什么，如何缓解它？

回调是 JavaScript 中处理异步操作的传统方式，它们是作为参数传递给其他函数的函数，并在异步操作完成时调用。Promise 是表示异步操作最终完成（或失败）的对象。与回调相比，Promise 提供了更结构化和可读的代码。通常，当处理复杂的异步操作、错误处理和代码可读性时，更倾向于使用 Promise 而不是回调。

回调地狱是指代码结构变得嵌套层次很深，每个回调都作为另一个回调的参数传递。这种嵌套会很快变得复杂，使代码难以理解，导致问题，如代码重复、错误处理问题以及难以维护和调试的困难。为了缓解回调地狱，可以使用几种方法，例如使用命名函数、使用控制流库（如 async.js 或 Promises）或使用现代 JavaScript 特性如 async/await。这些方法有助于扁平化代码结构，使其更可读和可维护，避免过多的回调嵌套。

#### 用 promises 解释 `.catch()` 方法的用途。它与 `.then()` 方法有什么不同？

promises 中的 .catch() 方法用于错误处理。它允许您指定一个回调函数，当 promise 在执行过程中被拒绝或遇到错误时将调用该回调函数。.then() 用于处理完成的 promises 和成功的结果。

#### `Promise.resolve` 和 `Promise.reject()` 的区别是什么？

Promise.resolve：它返回用给定值解析的 promises。如果提供的值已经是 Promise，则按原样返回。如果该值不是 Promise，Promise.Resolve() 将创建一个新的 Promise，该新 Promise 将立即使用提供的值进行解析。

Promise.reject()：它返回因给定原因或错误而被拒绝的 promises。所提供的原因或错误被视为拒绝 promises 的原因。

举个例子：

`const rejectedPromise = Promise.reject(new Error('Something went wrong'));`
通常，当您想要创建一个立即用特定值解析的 promises 时，通常使用 `Promise.resolve()`，而当您想要创建一个由于特定错误或原因而立即拒绝的 promises 时，则使用 `Promise.reject()`。


`Promise.resolve` 和 `Promise.reject` 是 JavaScript 中用于处理异步操作的两个方法。它们的主要区别在于它们如何创建和处理 Promise 对象：

 `Promise.resolve`

- **作用**：创建一个已解决（resolved）的 Promise 对象。
- **用法**：`Promise.resolve(value)`，其中 `value` 是你希望 Promise 解决的值。
- **示例**
    ```javascript
    const resolvedPromise = Promise.resolve('Resolved');
    resolvedPromise.then(console.log); // 输出: Resolved
    ```

- `Promise.resolve` 可以接受一个 Promise 对象，并等待其解决。
- `Promise.reject` 直接返回一个拒绝的 Promise，不会等待其他 Promise。


#### 使用 `Promise.resolve` 的场景

1. **快速返回一个已解决的 Promise**：

- 当你需要一个已经解决的 Promise 对象时，可以使用 `Promise.resolve`。例如，在测试中模拟异步操作的成功结果。

```javascript
function fetchData() {
  return Promise.resolve('Data fetched successfully');
}
fetchData().then(console.log); // 输出: Data fetched successfully
```

2. **将非 Promise 值转换为 Promise**：

- 如果你有一个非 Promise 的值，但需要将其作为 Promise 处理，可以使用 `Promise.resolve`。
```javascript
const value = 42;
const promiseValue = Promise.resolve(value);
promiseValue.then(console.log); // 输出: 42
```

3. **等待其他 Promise 解决**：

- 当你不确定传入的值是否是一个 Promise 时，可以使用 `Promise.resolve` 来确保它是一个 Promise。

```javascript
function maybePromise(value) {
  return Promise.resolve(value);
}
maybePromise(Promise.resolve('Resolved')).then(console.log); // 输出: Resolved
maybePromise('Not a promise').then(console.log); // 输出: Not a promise
```

#### 使用 `Promise.reject` 的场景

1. **快速返回一个已拒绝的 Promise**：

- 当你需要一个已经拒绝的 Promise 对象时，可以使用 `Promise.reject`。例如，在测试中模拟异步操作的失败结果。

```javascript
function fetchData() {
  return Promise.reject('Failed to fetch data');
}
fetchData().catch(console.error); // 输出: Failed to fetch data
```

2. **错误处理**：

- 在某些情况下，你可能需要手动创建一个拒绝的 Promise 来表示错误或异常情况。

```javascript
function validateInput(input) {
  if (input === '') {
	return Promise.reject('Input cannot be empty');
  }
  return Promise.resolve('Valid input');
}
validateInput('').catch(console.error); // 输出: Input cannot be empty
```


